<?xml version="1.0"?>
<robot xmlns:xacro="http://www.ros.org/wiki/xacro" name="arm">
    <xacro:include filename="$(find arm_mark1)/urdf/arm_gazebo.xacro"/>
    <xacro:include filename="$(find arm_mark1)/urdf/arm_ros2_control.xacro"/>

    <xacro:property name="PI" value="3.14159"/>
    <xacro:property name="EF" value="30.0"/>
    <xacro:property name="VEC" value="10.0"/>

    <xacro:macro name="default_inertial" params="mass">
        <inertial>
            <mass value="${mass}"/>
            <inertia ixx="1.0" ixy="0.0" ixz="0.0" iyy="1.0" iyz="0.0" izz="1.0"/>
               
            
        </inertial>
    </xacro:macro>

    <xacro:macro name="default_transmission" params="number">
        <transmission name="transimission_${number}">
        <plugin>transmission_interface/SimpleTransmission</plugin>
        <actuator name="motor_${number}" role="actuator1" />
        <joint name="joint_${number}" role="joint1" >
        <mechanical_reduction>1.0</mechanical_reduction>
        </joint>
        </transmission>
        </xacro:macro>

    <link name = "world"/>
    <link name="base_link">

        <xacro:default_inertial mass="1.0"/>
        <visual>
            <origin rpy="0.0 0.0 0.0" xyz="-0.5 -0.5 0.0"/>
            <geometry>
                <mesh filename="package://arm_mark1/meshes/basement.STL" scale="0.01 0.01 0.01"/>
            </geometry>
        </visual>

        <collision>
            <origin rpy="0.0 0.0 0.0" xyz="-0.5 -0.5 0.0"/>
            <geometry>
                <mesh filename="package://arm_mark1/meshes/basement.STL" scale="0.01 0.01 0.01"/>
            </geometry>
        </collision>
    </link>
    <joint name="virtual_joint" type="fixed">
        <parent link="world"/>
        <child link="base_link"/>
        <origin rpy="0 0 0" xyz="0 0 0"/>
    </joint>

    <link name="base_plate">
        <xacro:default_inertial mass="0.1"/>
        <visual>
            <origin rpy="0.0 0.0 0.0" xyz="-0.39 -0.39 -0.56"/>
            <geometry>
                <mesh filename="package://arm_mark1/meshes/base_plate.STL" scale="0.01 0.01 0.01"/>
            </geometry>
        </visual>

        <collision>
            <origin rpy="0.0 0.0 0.0" xyz="-0.39 -0.39 -0.56"/>
            <geometry>
                <mesh filename="package://arm_mark1/meshes/base_plate.STL" scale="0.01 0.01 0.01"/>
            </geometry>
        </collision>

    </link>
    <joint name="joint_1" type="revolute">
        <parent link="base_link"/>
        <child link="base_plate"/>
        <axis xyz="0.0 0.0 1.0"/>
        <origin rpy="0 0 0" xyz="0 0 0.307"/>
        <limit lower="-${PI/2}" upper="${PI/2}" effort="${EF}" velocity="${VEC}"/>
    </joint>

    <link name="forward_drive_arm">
        <xacro:default_inertial mass="0.1"/>
        <visual>
            <origin rpy="0.0 -${PI/2} ${PI/2}" xyz="0.19 0.06 -0.08"/>
            <geometry>
                <mesh filename="package://arm_mark1/meshes/forward_drive_arm.STL" scale="0.01 0.01 0.01"/>
            </geometry>
        </visual>

        <collision>
            <origin rpy="0.0 -${PI/2} ${PI/2}" xyz="0.19 0.06 -0.08"/>
            <geometry>
                <mesh filename="package://arm_mark1/meshes/forward_drive_arm.STL" scale="0.01 0.01 0.01"/>
            </geometry>
        </collision>

    </link>
    <joint name="joint_2" type="revolute">
        <parent link="base_plate"/>
        <child link="forward_drive_arm"/>
        <axis xyz="1.0 0.0 0.0"/>
        <origin rpy="0 0 0" xyz="0 0 0.35"/>
        <limit lower="-${PI/2}" upper="${PI/2}" effort="${EF}" velocity="${VEC}"/>
    </joint>

    <link name="horizontal_arm">
        <xacro:default_inertial mass="0.1"/>
        <visual>
            <origin rpy="${PI/2} 0.0 ${PI/2}" xyz="-0.03 -0.4 -0.06"/>
            <geometry>
                <mesh filename="package://arm_mark1/meshes/horizontal_arm.STL" scale="0.01 0.01 0.01"/>
            </geometry>
        </visual>

        <collision>
            <origin rpy="${PI/2} 0.0 ${PI/2}" xyz="-0.03 -0.4 -0.06"/>
            <geometry>
                <mesh filename="package://arm_mark1/meshes/horizontal_arm.STL" scale="0.01 0.01 0.01"/>
            </geometry>
        </collision>

    </link>
    <joint name="joint_3" type="revolute">
        <parent link="forward_drive_arm"/>
        <child link="horizontal_arm"/>
        <axis xyz="1.0 0.0 0.0"/>
        <origin rpy="0 0 0" xyz="0 0 0.8"/>
        <limit lower="0.0" upper="${PI}" effort="${EF}" velocity="${VEC}"/>
    </joint>


    <link name="claw_support">
        <xacro:default_inertial mass="0.05"/>
        <visual>
            <origin rpy="0.0 0.0 ${PI/2}"  xyz="0.15 0.0 -0.1"/>
            <geometry>
                <mesh filename="package://arm_mark1/meshes/claw_support.STL" scale="0.01 0.01 0.01"/>
            </geometry>
        </visual>
        <collision>
            <origin rpy="0.0 0.0 ${PI/2}"  xyz="0.15 0.0 -0.1"/>
            <geometry>
                <mesh filename="package://arm_mark1/meshes/claw_support.STL" scale="0.01 0.01 0.01"/>
            </geometry>
        </collision>

    </link>

    <joint name="joint_4" type="fixed">
        <parent link="horizontal_arm"/>
        <child link="claw_support"/>
        <origin rpy="0 0 0" xyz="0.0 0.82 0"/>
        
        
    </joint>


    <link name="right_finger">
        <xacro:default_inertial mass="0.01"/>
        <visual>
            <origin rpy="0.0 0.0 -${PI/2}"  xyz="-0.04 0.48 -0.04"/>
            <geometry>
                <mesh filename="package://arm_mark1/meshes/left_finger.STL" scale="0.01 0.01 0.01"/>
            </geometry>
        </visual>
        <collision>
            <origin rpy="0.0 0.0 -${PI/2}"  xyz="-0.04 0.48 -0.04"/>
            <geometry>
                <mesh filename="package://arm_mark1/meshes/left_finger.STL" scale="0.01 0.01 0.01"/>
            </geometry>
        </collision>

    </link>

    <link name="left_finger">
        <xacro:default_inertial mass="0.01"/>
        <visual>
            <origin rpy="0.0 0.0 -${PI/2}"  xyz="-0.08 0.48 -0.04"/>
            <geometry>
                <mesh filename="package://arm_mark1/meshes/right_finger.STL" scale="0.01 0.01 0.01"/>
            </geometry>
        </visual>
        <collision>
            <origin rpy="0.0 0.0 -${PI/2}"  xyz="-0.08 0.48 -0.04"/>
            <geometry>
                <mesh filename="package://arm_mark1/meshes/right_finger.STL" scale="0.01 0.01 0.01"/>
            </geometry>
        </collision>
    </link>





    <joint name="joint_5" type="revolute">
    
        <parent link="claw_support"/>
        <child link="left_finger"/>
        <origin rpy="0 0 0" xyz="0.11 0.2 -0.1" />
        <axis xyz="0.0 0.0 1.0"/>
        <origin rpy="0 0 0" xyz="0 0 0.1"/>
        <limit lower="-0.365" upper="0.0" effort="${EF}" velocity="${VEC}"/>
    </joint>
    <joint name="joint_6" type="revolute">
        <parent link="claw_support"/>
        <child link="right_finger"/>
        <origin rpy="0 0 0" xyz="-0.07 0.2 -0.1 "/>
        <axis xyz="0.0 0.0 1.0"/>
        <origin rpy="0 0 0" xyz="0 0 0.1"/>
        <mimic joint="joint_5" multiplier="-1"/>
        <limit lower="0.0" upper="-0.365" effort="${EF}" velocity="${VEC}"/>
        
    </joint>
    <xacro:default_transmission number="1" />
    <xacro:default_transmission number="2" />
    <xacro:default_transmission number="3" />
    <xacro:default_transmission number="5" />

</robot>